Workbook

Sheet Instructions
A1: ITC327W Project Progress and Contribution Workbook
A3: Use this workbook throughout the semester. Update it after each project phase and submit the same workbook again so that progress can be tracked over time.
A5: Sheet | B5: Purpose | D5: Evidence and Accountability Rules
A6: Project Overview | B6: Enter the group and project details. The dashboard summarises task progress automatically. | D6: 1 | E6: Every student must be assigned meaningful work in Microsoft Project.
A7: Task Progress | B7: Record planned and completed tasks, responsible students, dates, status, percentage completed and evidence. | D7: 2 | E7: Completed work must be supported by evidence such as GitHub activity, meeting records, document sections, screenshots or stakeholder communication.
A8: Individual Contributions | B8: Record the work personally completed by each student. Every entry must have evidence. | D8: 3 | E8: GitHub commits are not the only evidence. Planning, interviewing, documentation, coordination and quality review also count.
A9: Stakeholder Engagement | B9: Record meetings, calls and emails with the stakeholder and the main outcomes. | D9: 4 | E9: Do not record work as completed by a student when it was completed by someone else.
A10: Challenges & Actions | B10: Record project challenges, their effect and the corrective action taken. | D10: 5 | E10: Do not place passwords, API keys, identity numbers, private contact details or confidential records in this workbook or on GitHub.
A11: Phase Summary | B11: Provide a short summary of the phase, including achievements, outstanding work and participation concerns. | D11: 6 | E11: The confidential individual peer evaluation must be completed separately on Blackboard.
A12: Group Reflection | B12: Complete one shared reflection after each phase. Be honest and specific.
D13: Recommended Update Points
D14: Unit 1 / Phase 1 | E14: Planning, stakeholder engagement, requirements and initial SRS
D15: Phase 2 | E15: Architecture, UML, ERD and interface design
D16: Phase 3 | E16: Development, integration, testing and demonstration
D17: Final | E17: Overall project summary and final reflection

Sheet Project Overview
A1: Project Overview and Progress Dashboard
A3: Project Information | B3: Group Response | F3: Task Status | G3: Count
A4: Group name or number | B4: Group H | F4: Completed | G4: =COUNTIF('Task Progress'!H2:H101,"Completed") -> 15
A5: Project title | B5: SupaClean laundry and dry cleaning management system | F5: In Progress | G5: =COUNTIF('Task Progress'!H2:H101,"In Progress") -> 3
A6: Stakeholder or organisation | B6: SupaClean | F6: Not Started | G6: =COUNTIF('Task Progress'!H2:H101,"Not Started") -> 0
A7: Group mentor | F7: Delayed | G7: =COUNTIF('Task Progress'!H2:H101,"Delayed") -> 1
A8: Reporting phase | B8: Unit 1 / Phase 1 | F8: Blocked | G8: =COUNTIF('Task Progress'!H2:H101,"Blocked") -> 0
A9: Reporting period | B9: In Progress | F9: Overdue | G9: =COUNTIF('Task Progress'!M2:M101,"Overdue") -> 0
A10: Overall status | B10: In Progress
A11: Overall % complete | B11: Stakeholder engagement, requirements gathering, feasibility/risk planning and Phase 1 project scheduling have been allocated across the 10-member group. | F11: Contribution Summary | G11: Count
A12: Main achievement | B12: Final consolidation, evidence verification, group reflection and confirmation of individual completion records. | F12: Contribution entries | G12: =COUNTIF('Individual Contributions'!E3:E201,"?*") -> 47
A13: Main challenge | B13: Review and verify all Phase 1 documents, then finalise the Unit 1 submission. | F13: Verified entries | G13: =COUNTIFS('Individual Contributions'!E3:E201,"?*",'Individual Contributions'!J3:J201,"Yes") -> 47
A14: Next planned activity | F14: Unverified entries | G14: =COUNTIFS('Individual Contributions'!E3:E201,"?*",'Individual Contributions'!J3:J201,"No") -> 0
F15: Stakeholder engagements | G15: =COUNT('Stakeholder Engagement'!A3:A101) -> 1

Sheet Task Progress
A1: Task Progress Tracker
A2: Task ID | B2: Reporting Phase | C2: Activity | D2: Task Description | E2: Assigned Student(s) | F2: Start Date | G2: Due Date | H2: Status | I2: % Complete | J2: Evidence / Link | K2: Verified by Group | L2: Lecturer Comment | M2: Progress Flag
A3: U1-01 | B3: Unit 1 / Phase 1 | C3: Activity 1.1 | D3: Identify and confirm the external stakeholder | E3: Masendeke CP; Mahlangu P | F3: Tue 8/18/26 | G3: Wed 8/19/26 | H3: Completed | I3: 100 | K3: Yes | M3: =IF(D3="","",IF(H3="Completed","Completed",IF(H3="Blocked","Blocked",IF(H3="Delayed","Delayed",IF(AND(G3<>"",G3<TODAY(),H3<>"Completed"),"Overdue","On Track"))))) -> Completed
A4: U1-02 | B4: Unit 1 / Phase 1 | C4: Activity 1.1 | D4: Document the current process and problem | E4: Masendeke CP; Mahlangu P | F4: Tue 8/18/26 | H4: Completed | I4: 100 | K4: Yes | M4: =IF(D4="","",IF(H4="Completed","Completed",IF(H4="Blocked","Blocked",IF(H4="Delayed","Delayed",IF(AND(G4<>"",G4<TODAY(),H4<>"Completed"),"Overdue","On Track"))))) -> Completed
A5: U1-03 | B5: Unit 1 / Phase 1 | C5: Activity 1.1 | D5: Define the project aim, objectives and scope | E5: Masendeke CP; Mahlangu P | F5: Thu 8/20/26 | G5: Sat 8/22/26 | H5: Completed | I5: 100 | K5: Yes | M5: =IF(D5="","",IF(H5="Completed","Completed",IF(H5="Blocked","Blocked",IF(H5="Delayed","Delayed",IF(AND(G5<>"",G5<TODAY(),H5<>"Completed"),"Overdue","On Track"))))) -> Completed
A6: U1-04 | B6: Unit 1 / Phase 1 | C6: Activity 1.2 | D6: Prepare stakeholder interview questions | E6: Masendeke CP; Mahlangu P; Leeu FD; Maema KE | F6: Tue 8/18/26 | G6: Wed 8/19/26 | H6: Completed | I6: 100 | K6: Yes | M6: =IF(D6="","",IF(H6="Completed","Completed",IF(H6="Blocked","Blocked",IF(H6="Delayed","Delayed",IF(AND(G6<>"",G6<TODAY(),H6<>"Completed"),"Overdue","On Track"))))) -> Completed
A7: U1-05 | B7: Unit 1 / Phase 1 | C7: Activity 1.2 | D7: Conduct and document the stakeholder interview | E7: Masendeke CP; Mahlangu P; Leeu FD; Maema KE | F7: Tue 8/18/26 | G7: Wed 8/19/26 | H7: Completed | I7: 100 | K7: Yes | M7: =IF(D7="","",IF(H7="Completed","Completed",IF(H7="Blocked","Blocked",IF(H7="Delayed","Delayed",IF(AND(G7<>"",G7<TODAY(),H7<>"Completed"),"Overdue","On Track"))))) -> Completed
A8: U1-06 | B8: Unit 1 / Phase 1 | C8: Activity 1.3 | D8: Compile the initial SRS | E8: Leeu FD; Maema KE | F8: Sat 8/22/26 | G8: 29/8/2026 | H8: In Progress | I8: 100 | K8: Yes | M8: =IF(D8="","",IF(H8="Completed","Completed",IF(H8="Blocked","Blocked",IF(H8="Delayed","Delayed",IF(AND(G8<>"",G8<TODAY(),H8<>"Completed"),"Overdue","On Track"))))) -> On Track
A9: U1-07 | B9: Unit 1 / Phase 1 | C9: Activity 1.3 | D9: Create the initial Microsoft Project schedule | E9: Dasheka T; Ntlati TT | F9: Thu 8/27/26 | G9: 29/8/2026 | H9: Completed | I9: 100 | J9: https://cutfs-my.sharepoint.com/personal/224081629_stud_cut_ac_za/Documents/Documents/FreshnClean_ITC327W_Project_Progress_Tracker_Phase1.xlsx!Task%20Progress!AutoShape%204 | K9: Yes | M9: =IF(D9="","",IF(H9="Completed","Completed",IF(H9="Blocked","Blocked",IF(H9="Delayed","Delayed",IF(AND(G9<>"",G9<TODAY(),H9<>"Completed"),"Overdue","On Track"))))) -> Completed
A10: U1-08 | B10: Unit 1 / Phase 1 | C10: Activity 1.3 | D10: Create and configure the GitHub repository | E10: Maema KE | F10: Thu 8/27/26 | G10: Tue 8/25/26 | H10: Completed | I10: 100 | J10: https://eur02.safelinks.protection.outlook.com/?url=https%3A%2F%2Fgithub.com%2FMaema-kat%2FSupaClean-Dry-Clean-System-WIL-.git&data=05%7C02%7C224079714%40stud.cut.ac.za%7C64968eb4a5654296277d08df061ba4b6%7Cb940c14991b74bcfba2c0db8d817196d%7C0%7C0%7C639236387959627963%7CUnknown%7CTWFpbGZsb3d8eyJFbXB0eU1hcGkiOnRydWUsIlYiOiIwLjAuMDAwMCIsIlAiOiJXaW4zMiIsIkFOIjoiTWFpbCIsIldUIjoyfQ%3D%3D%7C0%7C%7C%7C&sdata=R6w8pdgcH1aIpo%2BOg9841qMGRH%2ByfwRRBH0Bt31sm9s%3D&reserved=0 | K10: Yes | M10: =IF(D10="","",IF(H10="Completed","Completed",IF(H10="Blocked","Blocked",IF(H10="Delayed","Delayed",IF(AND(G10<>"",G10<TODAY(),H10<>"Completed"),"Overdue","On Track"))))) -> Completed
A11: U1-09 | B11: Unit 1 / Phase 1 | C11: Activity 1.3 | D11: Create the initial Supabase project | E11: TBC | H11: Delayed | I11: 0 | K11: No | M11: =IF(D11="","",IF(H11="Completed","Completed",IF(H11="Blocked","Blocked",IF(H11="Delayed","Delayed",IF(AND(G11<>"",G11<TODAY(),H11<>"Completed"),"Overdue","On Track"))))) -> Delayed
A12: U1-10 | B12: Unit 1 / Phase 1 | C12: Activity 1.3 | D12: Complete the progress report and contribution record | E12: Dasheka T; Ntlati TT | F12: Fri 8/28/26 | G12: Mon 8/31/26 | H12: In Progress | I12: 100 | J12: https://cutfs-my.sharepoint.com/personal/224081629_stud_cut_ac_za/Documents/Documents/FreshnClean_ITC327W_Project_Progress_Tracker_Phase1.xlsx!Task%20Progress!AutoShape%204 | K12: Yes | M12: =IF(D12="","",IF(H12="Completed","Completed",IF(H12="Blocked","Blocked",IF(H12="Delayed","Delayed",IF(AND(G12<>"",G12<TODAY(),H12<>"Completed"),"Overdue","On Track"))))) -> On Track
A13: U1-11 | B13: Unit 1 / Phase 1 | C13: Activity 1.3 | D13: Complete the Unit 1 group reflection | E13: All 10 group members | F13: Tue 8/11/26 | G13: Fri 8/14/26 | H13: Completed | I13: 100 | K13: Yes | M13: =IF(D13="","",IF(H13="Completed","Completed",IF(H13="Blocked","Blocked",IF(H13="Delayed","Delayed",IF(AND(G13<>"",G13<TODAY(),H13<>"Completed"),"Overdue","On Track"))))) -> Completed
A14: U1-12 | B14: Unit 1 / Phase 1 | C14: Activity 1.1 | D14: Project kickoff meeting | E14: Dasheka T; Leeu FD; Maema KE; Maleke KT; Masendeke CP; Mahlangu P; Mojakwe KB; Moretlwe RK; Ntlati TT; Stallenberg BC | F14: Tue 8/18/26 | G14: Tue 8/18/26 | H14: Completed | I14: 100 | K14: Yes | M14: =IF(D14="","",IF(H14="Completed","Completed",IF(H14="Blocked","Blocked",IF(H14="Delayed","Delayed",IF(AND(G14<>"",G14<TODAY(),H14<>"Completed"),"Overdue","On Track"))))) -> Completed
A15: U1-13 | B15: Unit 1 / Phase 1 | C15: Activity 1.1 | D15: Gather functional requirements | E15: Leeu FD; Maema KE | F15: Mon 8/24/26 | G15: Tue 8/25/26 | H15: Completed | I15: 100 | K15: Yes | M15: =IF(D15="","",IF(H15="Completed","Completed",IF(H15="Blocked","Blocked",IF(H15="Delayed","Delayed",IF(AND(G15<>"",G15<TODAY(),H15<>"Completed"),"Overdue","On Track"))))) -> Completed
A16: U1-14 | B16: Unit 1 / Phase 1 | C16: Activity 1.1 | D16: Gather non-functional requirements | E16: Leeu FD; Maema KE | F16: Wed 8/26/26 | G16: Thu 8/27/26 | H16: Completed | I16: 100 | K16: Yes | M16: =IF(D16="","",IF(H16="Completed","Completed",IF(H16="Blocked","Blocked",IF(H16="Delayed","Delayed",IF(AND(G16<>"",G16<TODAY(),H16<>"Completed"),"Overdue","On Track"))))) -> Completed
A17: U1-15 | B17: Unit 1 / Phase 1 | C17: Activity 1.3 | D17: Technical feasibility | E17: Maleke KT; Moretlwe RK | F17: Sat 8/22/26 | G17: Sat 8/22/26 | H17: Completed | I17: 100 | K17: Yes | M17: =IF(D17="","",IF(H17="Completed","Completed",IF(H17="Blocked","Blocked",IF(H17="Delayed","Delayed",IF(AND(G17<>"",G17<TODAY(),H17<>"Completed"),"Overdue","On Track"))))) -> Completed
A18: U1-16 | B18: Unit 1 / Phase 1 | C18: Activity 1.3 | D18: Economical feasibility | E18: Maema KT; Moretlwe RK | F18: Tue 8/25/26 | G18: Tue 8/25/26 | H18: Completed | I18: 100 | K18: Yes | M18: =IF(D18="","",IF(H18="Completed","Completed",IF(H18="Blocked","Blocked",IF(H18="Delayed","Delayed",IF(AND(G18<>"",G18<TODAY(),H18<>"Completed"),"Overdue","On Track"))))) -> Completed
A19: U1-17 | B19: Unit 1 / Phase 1 | C19: Activity 1.3 | D19: Create project risk register | E19: Mojakwe KB; Stallenberg BC | F19: Tue 8/25/26 | G19: Wed 8/26/26 | H19: In Progress | I19: 50 | K19: Yes | M19: =IF(D19="","",IF(H19="Completed","Completed",IF(H19="Blocked","Blocked",IF(H19="Delayed","Delayed",IF(AND(G19<>"",G19<TODAY(),H19<>"Completed"),"Overdue","On Track"))))) -> On Track
A20: U1-18 | B20: Unit 1 / Phase 1 | C20: Activity 1.3 | D20: Risk review meeting | E20: Mojakwe KB; Stallenberg BC | F20: Thu 8/27/26 | G20: Thu 8/27/26 | H20: Completed | I20: 100 | K20: Yes | M20: =IF(D20="","",IF(H20="Completed","Completed",IF(H20="Blocked","Blocked",IF(H20="Delayed","Delayed",IF(AND(G20<>"",G20<TODAY(),H20<>"Completed"),"Overdue","On Track"))))) -> Completed
A21: U1-19 | B21: Unit 1 / Phase 1 | C21: Activity 1.3 | D21: Review all Phase 1 documents | E21: Dasheka T; Leeu FD; Maema KE; Maleke KT; Masendeke CP; Mahlangu P; Mojakwe KB; Moretlwe RK; Ntlati TT; Stallenberg BC | F21: Sat 8/29/26 | G21: Mon 8/31/26 | H21: Completed | I21: 100 | K21: Yes | M21: =IF(D21="","",IF(H21="Completed","Completed",IF(H21="Blocked","Blocked",IF(H21="Delayed","Delayed",IF(AND(G21<>"",G21<TODAY(),H21<>"Completed"),"Overdue","On Track"))))) -> Completed
M22: =IF(D22="","",IF(H22="Completed","Completed",IF(H22="Blocked","Blocked",IF(H22="Delayed","Delayed",IF(AND(G22<>"",G22<TODAY(),H22<>"Completed"),"Overdue","On Track")))))
M23: =IF(D23="","",IF(H23="Completed","Completed",IF(H23="Blocked","Blocked",IF(H23="Delayed","Delayed",IF(AND(G23<>"",G23<TODAY(),H23<>"Completed"),"Overdue","On Track")))))
M24: =IF(D24="","",IF(H24="Completed","Completed",IF(H24="Blocked","Blocked",IF(H24="Delayed","Delayed",IF(AND(G24<>"",G24<TODAY(),H24<>"Completed"),"Overdue","On Track")))))
M25: =IF(D25="","",IF(H25="Completed","Completed",IF(H25="Blocked","Blocked",IF(H25="Delayed","Delayed",IF(AND(G25<>"",G25<TODAY(),H25<>"Completed"),"Overdue","On Track")))))
M26: =IF(D26="","",IF(H26="Completed","Completed",IF(H26="Blocked","Blocked",IF(H26="Delayed","Delayed",IF(AND(G26<>"",G26<TODAY(),H26<>"Completed"),"Overdue","On Track")))))
M27: =IF(D27="","",IF(H27="Completed","Completed",IF(H27="Blocked","Blocked",IF(H27="Delayed","Delayed",IF(AND(G27<>"",G27<TODAY(),H27<>"Completed"),"Overdue","On Track")))))
M28: =IF(D28="","",IF(H28="Completed","Completed",IF(H28="Blocked","Blocked",IF(H28="Delayed","Delayed",IF(AND(G28<>"",G28<TODAY(),H28<>"Completed"),"Overdue","On Track")))))
M29: =IF(D29="","",IF(H29="Completed","Completed",IF(H29="Blocked","Blocked",IF(H29="Delayed","Delayed",IF(AND(G29<>"",G29<TODAY(),H29<>"Completed"),"Overdue","On Track")))))
M30: =IF(D30="","",IF(H30="Completed","Completed",IF(H30="Blocked","Blocked",IF(H30="Delayed","Delayed",IF(AND(G30<>"",G30<TODAY(),H30<>"Completed"),"Overdue","On Track")))))
M31: =IF(D31="","",IF(H31="Completed","Completed",IF(H31="Blocked","Blocked",IF(H31="Delayed","Delayed",IF(AND(G31<>"",G31<TODAY(),H31<>"Completed"),"Overdue","On Track")))))
M32: =IF(D32="","",IF(H32="Completed","Completed",IF(H32="Blocked","Blocked",IF(H32="Delayed","Delayed",IF(AND(G32<>"",G32<TODAY(),H32<>"Completed"),"Overdue","On Track")))))
M33: =IF(D33="","",IF(H33="Completed","Completed",IF(H33="Blocked","Blocked",IF(H33="Delayed","Delayed",IF(AND(G33<>"",G33<TODAY(),H33<>"Completed"),"Overdue","On Track")))))
... M101: =IF(D101="","",IF(H101="Completed","Completed",IF(H101="Blocked","Blocked",IF(H101="Delayed","Delayed",IF(AND(G101<>"",G101<TODAY(),H101<>"Completed"),"Overdue","On Track")))))

Sheet Individual Contributions
A1: Individual Contribution Record
A2: Student Name | B2: Student Number | C2: Reporting Phase | D2: Activity | E2: Assigned Responsibility | F2: Work Personally Completed | G2: Date Completed | H2: Hours Spent | I2: Evidence / Link | J2: Verified by Group | K2: Verification Date | L2: Notes
A3: Dasheka T | B3: 219007064 | C3: Unit 1 / Phase 1 | D3: Project kickoff meeting | E3: Project kickoff meeting | F3: Participated in the project kickoff meeting and contributed to the initial discussion of the project scope, objectives and responsibilities. | G3: Tue 8/18/26 | H3: 3 | J3: Yes | K3: 46253 | L3: Team alignment achieved on the high-level roadmap, SRS scope, and communication protocols established during the session.
A4: Leeu FD | B4: 223044569 | C4: Unit 1 / Phase 1 | D4: Project kickoff meeting | E4: Project kickoff meeting | F4: Participated in the project kickoff meeting and contributed to the initial discussion of the project scope, objectives and responsibilities. | G4: Tue 8/18/26 | H4: 3 | J4: Yes | K4: 46253 | L4: Team alignment achieved on the high-level roadmap, SRS scope, and communication protocols established during the session.
A5: Maema KE | B5: 224079714 | C5: Unit 1 / Phase 1 | D5: Project kickoff meeting | E5: Project kickoff meeting | F5: Participated in the project kickoff meeting and contributed to the initial discussion of the project scope, objectives and responsibilities. | G5: Tue 8/18/26 | H5: 3 | J5: Yes | K5: 46253 | L5: Team alignment achieved on the high-level roadmap, SRS scope, and communication protocols established during the session.
A6: Maleke KT | B6: 222009259 | C6: Unit 1 / Phase 1 | D6: Project kickoff meeting | E6: Project kickoff meeting | F6: Participated in the project kickoff meeting and contributed to the initial discussion of the project scope, objectives and responsibilities. | G6: Tue 8/18/26 | H6: 3 | J6: Yes | K6: 46253 | L6: Team alignment achieved on the high-level roadmap, SRS scope, and communication protocols established during the session.
A7: Masendeke CP | B7: 224043099 | C7: Unit 1 / Phase 1 | D7: Project kickoff meeting | E7: Project kickoff meeting | F7: Participated in the project kickoff meeting and contributed to the initial discussion of the project scope, objectives and responsibilities. | G7: Tue 8/18/26 | H7: 3 | J7: Yes | K7: 46253 | L7: Team alignment achieved on the high-level roadmap, SRS scope, and communication protocols established during the session.
A8: Mhlangu P | C8: Unit 1 / Phase 1 | D8: Project kickoff meeting | E8: Project kickoff meeting | F8: Participated in the project kickoff meeting and contributed to the initial discussion of the project scope, objectives and responsibilities. | G8: Tue 8/18/26 | H8: 3 | J8: Yes | K8: 46253 | L8: Team alignment achieved on the high-level roadmap, SRS scope, and communication protocols established during the session.
A9: Mojakwe KB | B9: 223032987 | C9: Unit 1 / Phase 1 | D9: Project kickoff meeting | E9: Project kickoff meeting | F9: Participated in the project kickoff meeting and contributed to the initial discussion of the project scope, objectives and responsibilities. | G9: Tue 8/18/26 | H9: 3 | J9: Yes | K9: 46253 | L9: Team alignment achieved on the high-level roadmap, SRS scope, and communication protocols established during the session.
A10: Moretlwe RK | B10: 221012635 | C10: Unit 1 / Phase 1 | D10: Project kickoff meeting | E10: Project kickoff meeting | F10: Participated in the project kickoff meeting and contributed to the initial discussion of the project scope, objectives and responsibilities. | G10: Tue 8/18/26 | H10: 3 | J10: Yes | K10: 46253 | L10: Team alignment achieved on the high-level roadmap, SRS scope, and communication protocols established during the session.
A11: Ntlati TT | B11: 224081629 | C11: Unit 1 / Phase 1 | D11: Project kickoff meeting | E11: Project kickoff meeting | F11: Participated in the project kickoff meeting and contributed to the initial discussion of the project scope, objectives and responsibilities. | G11: Tue 8/18/26 | H11: 3 | J11: Yes | K11: 46253 | L11: Team alignment achieved on the high-level roadmap, SRS scope, and communication protocols established during the session.
A12: Stallenberg BC | B12: 224081442 | C12: Unit 1 / Phase 1 | D12: Project kickoff meeting | E12: Project kickoff meeting | F12: Participated in the project kickoff meeting and contributed to the initial discussion of the project scope, objectives and responsibilities. | G12: Tue 8/18/26 | H12: 3 | J12: Yes | K12: 46253 | L12: Team alignment achieved on the high-level roadmap, SRS scope, and communication protocols established during the session.
A13: Masendeke CP | B13: 224043099 | C13: Unit 1 / Phase 1 | D13: Identify stakeholder & organization | E13: Identify stakeholder & organization | F13: Assisted with identifying and documenting the stakeholder, organisation and relevant business context. | G13: 46263 | H13: 5 | J13: Yes | K13: 46253 | L13: Special focus placed on resource owners and cross-functional team leads flagged in recent schedule updates.
A14: Mhlangu P | C14: Unit 1 / Phase 1 | D14: Identify stakeholder & organization | E14: Identify stakeholder & organization | F14: TBC – confirm personally completed work and evidence | G14: 46263 | H14: 5 | J14: Yes | K14: 46253 | L14: Special focus placed on resource owners and cross-functional team leads flagged in recent schedule updates.
A15: Masendeke CP | B15: 224043099 | C15: Unit 1 / Phase 1 | D15: Stakeholder interviews/meeting | E15: Stakeholder interviews/meeting | F15: Participated in the stakeholder meeting and contributed questions and observations regarding the current business process and system requirements. | G15: 46263 | H15: 3 | J15: Yes | K15: 46253 | L15: Primary objective is to secure sign-off on the baseline timeline and confirm mitigation ownership for high-priority risks.
A16: Mhlangu P | C16: Unit 1 / Phase 1 | D16: Stakeholder interviews/meeting | E16: Stakeholder interviews/meeting | F16: TBC – confirm personally completed work and evidence | G16: 46263 | H16: 3 | J16: Yes | K16: 46253 | L16: Primary objective is to secure sign-off on the baseline timeline and confirm mitigation ownership for high-priority risks.
A17: Leeu FD | B17: 223044569 | C17: Unit 1 / Phase 1 | D17: Stakeholder interviews/meeting | E17: Stakeholder interviews/meeting | F17: TBC – confirm personally completed work and evidence | G17: 46263 | H17: 3 | J17: Yes | K17: 46253 | L17: Primary objective is to secure sign-off on the baseline timeline and confirm mitigation ownership for high-priority risks.
A18: Maema KE | B18: 224079714 | C18: Unit 1 / Phase 1 | D18: Stakeholder interviews/meeting | E18: Stakeholder interviews/meeting | F18: TBC – confirm personally completed work and evidence | G18: 46263 | H18: 3 | J18: Yes | K18: 46253 | L18: Primary objective is to secure sign-off on the baseline timeline and confirm mitigation ownership for high-priority risks.
A19: Masendeke CP | B19: 224043099 | C19: Unit 1 / Phase 1 | D19: Problem analysis & evidence collection | E19: Problem analysis & evidence collection | F19: Assisted with analysing the current process and collecting evidence of the stakeholder's identified problems and needs. | G19: 46263 | H19: 2 | J19: Yes | K19: 46253
A20: Mhlangu P | C20: Unit 1 / Phase 1 | D20: Problem analysis & evidence collection | E20: Problem analysis & evidence collection | F20: TBC – confirm personally completed work and evidence | G20: 46263 | H20: 2 | J20: Yes | K20: 46253
A21: Leeu FD | B21: 223044569 | C21: Unit 1 / Phase 1 | D21: Gather functional requirements | E21: Gather functional requirements | F21: Assisted with refining and documenting the functional requirements for the proposed system. | G21: 46263 | H21: 2 | J21: Yes | K21: 46253 | L21: All identified features align directly with the business goals approved in the operational feasibility study.
A22: Maema KE | B22: 224079714 | C22: Unit 1 / Phase 1 | D22: Gather functional requirements | E22: Gather functional requirements | F22: Identified and documented functional requirements based on the stakeholder's needs and current business process. | G22: 46263 | H22: 2 | J22: Yes | K22: 46253 | L22: All identified features align directly with the business goals approved in the operational feasibility study.
A23: Leeu FD | B23: 223044569 | C23: Unit 1 / Phase 1 | D23: Gather non-functional requirements | E23: Gather non-functional requirements | F23: Assisted with reviewing and documenting the non-functional requirements to ensure they were relevant to the proposed solution. | G23: 46263 | H23: 1.5 | J23: Yes | K23: 46253 | L23: Established clear benchmarks (e.g., page load times, uptime targets, data encryption standards) that the engineering team must meet.
A24: Maema KE | B24: 224079714 | C24: Unit 1 / Phase 1 | D24: Gather non-functional requirements | E24: Gather non-functional requirements | F24: Identified relevant non-functional requirements relating to usability, performance, security, availability and system quality. | G24: 46263 | H24: 1.5 | J24: Yes | K24: 46253 | L24: Established clear benchmarks (e.g., page load times, uptime targets, data encryption standards) that the engineering team must meet.
A25: Leeu FD | B25: 223044569 | C25: Unit 1 / Phase 1 | D25: Write software requirements specification | E25: Write software requirements specification | F25: Assisted with compiling and reviewing the Software Requirements Specification, including requirements, scope and integration considerations. | G25: 46263 | H25: 4 | J25: Yes | K25: 46253 | L25: Ensured all technical specifications map directly to the approved MS Project schedule milestones and risk mitigation boundaries.
A26: Maema KE | B26: 224079714 | C26: Unit 1 / Phase 1 | D26: Write software requirements specification | E26: Write software requirements specification | F26: Drafted and refined sections of the Software Requirements Specification based on the stakeholder analysis and requirements gathered. | G26: 46263 | H26: 4 | J26: Yes | K26: 46253 | L26: Ensured all technical specifications map directly to the approved MS Project schedule milestones and risk mitigation boundaries.
A27: Maleke KT | B27: 222009259 | C27: Unit 1 / Phase 1 | D27: Technical feasibility | E27: Technical feasibility | F27: Evaluated the technical feasibility of the proposed solution, including the technologies, integration requirements and available technical skills. | G27: 46263 | H27: 3 | J27: Yes | K27: 46253 | L27: Confirmed that the technologies required for the SRS implementation are viable and sustainable within our current tech stack.
A28: Moretlwe RK | B28: 221012635 | C28: Unit 1 / Phase 1 | D28: Technical feasibility | E28: Technical feasibility | F28: Assisted with assessing the technical requirements, technology constraints and integration feasibility of the proposed system. | G28: 46263 | H28: 3 | J28: Yes | K28: 46253 | L28: Confirmed that the technologies required for the SRS implementation are viable and sustainable within our current tech stack.
A29: Maema KT | B29: 224079714 | C29: Unit 1 / Phase 1 | D29: Economical feasibility | E29: Economical feasibility | F29: TBC – confirm personally completed work and evidence | G29: 46263 | H29: 3 | J29: Yes | K29: 46253 | L29: The financial projections confirm the project is cost-effective and fits within the designated corporate budget allocations.
A30: Moretlwe RK | B30: 221012635 | C30: Unit 1 / Phase 1 | D30: Economical feasibility | E30: Economical feasibility | F30: Assisted with assessing the economic feasibility of the project and the resources required for development. | G30: 46263 | H30: 3 | J30: Yes | K30: 46253 | L30: The financial projections confirm the project is cost-effective and fits within the designated corporate budget allocations.
A31: Mojakwe KB | B31: 223032987 | C31: Unit 1 / Phase 1 | D31: Create project risk register | E31: Create project risk register | F31: Identified project risks and documented their categories, likelihood, impact, risk scores, mitigation actions and owners. | G31: 46263 | H31: 4.5 | J31: Yes | K31: 46253 | L31: Highlighting critical path dependencies that pose the highest threat to the baseline timeline.
A32: Stallenberg BC | B32: 224081442 | C32: Unit 1 / Phase 1 | D32: Create project risk register | E32: Create project risk register | F32: Assisted with developing the project risk register and documenting appropriate mitigation and contingency actions. | G32: 46263 | H32: 4.5 | J32: Yes | K32: 46253 | L32: Highlighting critical path dependencies that pose the highest threat to the baseline timeline.
... A34: Stallenberg BC | B34: 224081442 | C34: Unit 1 / Phase 1 | D34: Risk review meeting | E34: Risk review meeting | F34: Participated in the risk review and assisted with reviewing risk status, mitigation actions and the highest-priority project risks. | G34: 46263 | H34: 3 | J34: Yes | K34: 46253 | L34: Highlighting critical path dependencies that pose the highest threat to the baseline timeline.
A35: Dasheka T | B35: 219007064 | C35: Unit 1 / Phase 1 | D35: Create Microsoft Project schedule | E35: Create Microsoft Project schedule | F35: Created and updated project activities, durations, dates, dependencies, responsibilities and milestones in Microsoft Project. | G35: 46263 | H35: 3.5 | I35: https://cutfs-my.sharepoint.com/personal/224081629_stud_cut_ac_za/Documents/Documents/FreshnClean_ITC327W_Project_Progress_Tracker_Phase1.xlsx!Task%20Progress!AutoShape%204 | J35: Yes | K35: 46253 | L35: Ready to transition from planning to active tracking.
A36: Ntlati TT | B36: 224081629 | C36: Unit 1 / Phase 1 | D36: Create Microsoft Project schedule | E36: Create Microsoft Project schedule | F36: Assisted with developing and reviewing the Microsoft Project schedule to ensure the Phase 1 activities reflected the actual project progress. | G36: 46263 | H36: 3.5 | I36: https://cutfs-my.sharepoint.com/personal/224081629_stud_cut_ac_za/Documents/Documents/FreshnClean_ITC327W_Project_Progress_Tracker_Phase1.xlsx!Task%20Progress!AutoShape%204 | J36: Yes | K36: 46253 | L36: Ready to transition from planning to active tracking.
A37: Maema KE | B37: 224079714 | C37: Unit 1 / Phase 1 | D37: Create GitHub repository & README | E37: Create GitHub repository & README | F37: Contributed to setting up and reviewing the GitHub repository and README and ensuring the project documentation was organised. | H37: 3 | I37: https://eur02.safelinks.protection.outlook.com/?url=https%3A%2F%2Fgithub.com%2FMaema-kat%2FSupaClean-Dry-Clean-System-WIL-.git&data=05%7C02%7C224079714%40stud.cut.ac.za%7C64968eb4a5654296277d08df061ba4b6%7Cb940c14991b74bcfba2c0db8d817196d%7C0%7C0%7C639236387959627963%7CUnknown%7CTWFpbGZsb3d8eyJFbXB0eU1hcGkiOnRydWUsIlYiOiIwLjAuMDAwMCIsIlAiOiJXaW4zMiIsIkFOIjoiTWFpbCIsIldUIjoyfQ%3D%3D%7C0%7C%7C%7C&sdata=R6w8pdgcH1aIpo%2BOg9841qMGRH%2ByfwRRBH0Bt31sm9s%3D&reserved=0 | J37: Yes | K37: 46253 | L37: Ensured the README includes clear setup instructions, project architecture notes, and a high-level timeline linking back to our master milestones.
A38: Dasheka T | B38: 219007064 | C38: Unit 1 / Phase 1 | D38: Progress tracker | E38: Progress tracker | F38: Reviewed and contributed to updating the project progress tracker to ensure activities and individual contributions were accurately recorded. | H38: 4 | J38: Yes | K38: 46253 | L38: All current metrics are live and reflect accurate project health.
A39: Ntlati TT | B39: 224081629 | C39: Unit 1 / Phase 1 | D39: Progress tracker | E39: Progress tracker | F39: Reviewed and contributed to updating the project progress tracker to ensure activities and individual contributions were accurately recorded. | H39: 4 | J39: Yes | K39: 46253 | L39: All current metrics are live and reflect accurate project health.
A40: Dasheka T | B40: 219007064 | C40: Unit 1 / Phase 1 | D40: Review all Phase 1 documents | E40: Review all Phase 1 documents | F40: Reviewed the Phase 1 documents for completeness, consistency and alignment with the project requirements. | H40: 3.5 | J40: Yes | K40: 46253 | L40: This comprehensive review ensures absolute alignment between business expectations, technical constraints, and the development timeline before transition to Phase 2.
A41: Leeu FD | B41: 223044569 | C41: Unit 1 / Phase 1 | D41: Review all Phase 1 documents | E41: Review all Phase 1 documents | F41: Reviewed the Phase 1 documents for completeness, consistency and alignment with the project requirements. | H41: 3.5 | J41: Yes | K41: 46253 | L41: This comprehensive review ensures absolute alignment between business expectations, technical constraints, and the development timeline before transition to Phase 2.
...

Sheet Stakeholder Engagement
A1: Stakeholder Engagement Record
A2: Date | B2: Reporting Phase | C2: Type of Engagement | D2: Purpose | E2: Students Present | F2: Stakeholder Present / Role | G2: Main Findings | H2: Action Required | I2: Evidence / Link
A3: 46253 | B3: Unit 1 / Phase 1 | C3: Stakeholder meeting/interview | D3: Understand FreshnClean's current process, problems, requirements and proposed digital solution. | E3: Masendeke CP; Mahlangu P; Leeu FD; Maema KE | F3: SupaClean Manager | G3: Clarified the laundry/dry-cleaning workflow, customer order process, pickup/drop-off points, central processing, order status/collection, operational roles and existing ticket/docket process. | H3: Confirm outstanding details including ticket/docket integration, referral/discount rules, final pickup/drop-off details and exceptional garment notification procedures. | I3: #VALUE!
I4: #VALUE!
I5: #VALUE!
I6: #VALUE!

Sheet Challenges & Actions
A1: Challenges and Corrective Actions
A2: Date Identified | B2: Reporting Phase | C2: Challenge | D2: Effect on Progress | E2: Corrective Action | F2: Responsible Student | G2: Target Date | H2: Status
A3: 46252 | B3: Unit 1 / Phase 1 | C3: Could not identify stakeholder | D3: Going broader to other places or busy businesses places to identify more businesses | E3: Manage to go to placess with more stores/businesses and quickly found potential stakeholder | F3: Masendeke CP; Mahlangu P | H3: Resolved
A4: 46261 | B4: Unit 1 / Phase 1 | C4: Some requirements still require stakeholder confirmation. | D4: Could delay finalisation of parts of the SRS and system design. | E4: Record the outstanding items and confirm them with the stakeholder before final design approval. | F4: All 10 group members | H4: Resolved

Sheet Phase Summary
A1: Phase Progress Summary
A3: Summary Information | B3: Group Response | D3: Phase Completion Checklist
A4: Reporting phase | B4: Unit 1 / Phase 1 | D4: Initial or updated SRS completed | E4: In Progress
A5: Reporting period | B5: 18 August 2026 – 31 August 2026 | D5: Progress report updated | E5: In Progress
A6: Overall phase status | B6: In Progress | D6: Individual contributions recorded | E6: Yes
A7: What was completed during this phase? | B7: The group completed stakeholder engagement and developed the initial understanding of the FreshnClean problem, requirements, feasibility, risks and project structure. Responsibilities were allocated across the 10 group members, including Microsoft Project, GitHub and the Progress Tracker. | D7: Stakeholder engagement recorded | E7: Yes
A8: What remains incomplete? | B8: Final document review, evidence verification, individual contribution confirmation, group reflection and any outstanding stakeholder clarifications remain. | D8: Challenges and actions updated | E8: Yes
A9: Why is it incomplete? | B9: Some requirements still need confirmation, and the group must verify that all Phase 1 artefacts agree with the actual work completed by each member. | D9: Group reflection completed | E9: Yes
A10: Which contributions were particularly important? | B10: Stakeholder engagement and requirements work were particularly important, together with the Microsoft Project schedule, risk register, SRS and evidence/document review. | D10: Microsoft Project updated | E10: Yes
A11: Were there participation concerns? | B11: TBC – confirm any participation concerns using the group's actual contribution evidence. | D11: GitHub evidence available | E11: TBC
A12: What will the group improve in the next phase? | B12: Use clearer task ownership and earlier coordination in Phase 2, while keeping the SRS, Microsoft Project, Progress Tracker, GitHub and stakeholder evidence aligned. | D12: Confidential peer check completed | E12: TBC
A13: Main priority for the next phase | B13: Complete Phase 1 document review and evidence verification, then move into system architecture and design.

Sheet Group Reflection
A1: Group Reflection
A3: Reflection Information | B3: Group Response | D3: Reflection Guidance
A4: Reporting phase | B4: Unit 1 / Phase 1 | D4: Length | E4: Approximately 300–400 words in total.
A5: Project title | B5: FreshnClean | D5: Focus | E5: Discuss the group’s actual experience, not the activity instructions.
A6: Most important learning from this phase | B6: The main learning from Phase 1 was the importance of understanding the stakeholder's real operational workflow before designing the system. The group identified the customer journey, pickup/drop-off process, processing workflow, order status and key system requirements. | D6: Honesty | E6: Identifying a genuine challenge will not disadvantage the group when an improvement action is provided.
A7: What went well and why? | B7: Stakeholder engagement and requirements gathering established a clearer project direction. The group also divided Phase 1 responsibilities across the 10 members.Thorough Feasibility Alignment: Separating the operational, technical, and economic feasibility studies provided a rock-solid business case and prevented early scope creep.Proactive Stakeholder Engagement: Identifying and mapping key stakeholders right after the MS Project plan baseline ensured high attendance and valuable input during the kick-off meeting.Strong Technical Foundation: Initializing the GitHub repository early and embedding the SRS benchmarks directly into the README.md gave the development team immediate clarity on technical constraints. | D7: Evidence | E7: Ensure that claims about participation agree with the contribution record, Microsoft Project and GitHub.
A8: What was difficult and why? | B8: The group still needs to confirm several stakeholder details and ensure that the SRS, Microsoft Project, Progress Tracker, GitHub evidence and individual contribution records all agree.Timeline Estimation Discrepancy: The gathering of functional and non-functional requirements took 20% longer than initially estimated in the MS Project plan due to conflicting stakeholder feedback.Review Bottlenecks: Reviewing every single document at the end of Phase 1 created a documentation bottleneck, delaying the final sign-off by several days | D8: Research use | E8: Student work may only be used for research after the required ethical approval and consent processes.
A9: How were tasks divided among members? | B9: Work was divided across stakeholder analysis, requirements, feasibility, risk management, Microsoft Project, GitHub and progress tracking. The final Phase 1 document review is assigned to everyone.
A10: Did all members contribute fairly? Explain. | B10: Yes everyone managed to do the parts assigned to them by the group and its fair because the group did not appose to any of the way the work was divided
A11: How did the group handle disagreements or delays? | B11: The group used task allocation and follow-up review to manage work. Any delays or disagreements should be recorded in the Challenges & Actions sheet rather than assumed.
A12: What did the group learn from the stakeholder? | B12: The stakeholder clarified the current laundry/dry-cleaning workflow, customer process, pickup/drop-off points, operational roles, order status and the existing ticket/docket process.
A13: Improvement action 1 for the next phase | B13: Assign Phase 2 responsibilities before design work begins and confirm each member's deliverables.
A14: Improvement action 2 for the next phase | B14: Use a shared evidence/checking process so that the SRS, MPP, GitHub and Progress Tracker remain consistent.
A15: Priority for the next phase | B15: Complete Phase 1 document review and evidence verification, then begin system architecture and design.
